[2025-03-03T10:51:38.448+0000] {taskinstance.py:1956} INFO - Dependencies all met for dep_context=non-requeueable deps ti=<TaskInstance: stock_price_prediction.run_stock_prediction manual__2025-03-03T10:48:01.103488+00:00 [queued]>
[2025-03-03T10:51:38.459+0000] {taskinstance.py:1956} INFO - Dependencies all met for dep_context=requeueable deps ti=<TaskInstance: stock_price_prediction.run_stock_prediction manual__2025-03-03T10:48:01.103488+00:00 [queued]>
[2025-03-03T10:51:38.460+0000] {taskinstance.py:2170} INFO - Starting attempt 2 of 2
[2025-03-03T10:51:38.474+0000] {taskinstance.py:2191} INFO - Executing <Task(PythonOperator): run_stock_prediction> on 2025-03-03 10:48:01.103488+00:00
[2025-03-03T10:51:38.480+0000] {standard_task_runner.py:60} INFO - Started process 93 to run task
[2025-03-03T10:51:38.482+0000] {standard_task_runner.py:87} INFO - Running: ['***', 'tasks', 'run', 'stock_price_prediction', 'run_stock_prediction', 'manual__2025-03-03T10:48:01.103488+00:00', '--job-id', '26', '--raw', '--subdir', 'DAGS_FOLDER/stock_prediction_dag.py', '--cfg-path', '/tmp/tmplvhew_j3']
[2025-03-03T10:51:38.485+0000] {standard_task_runner.py:88} INFO - Job 26: Subtask run_stock_prediction
[2025-03-03T10:51:38.532+0000] {task_command.py:423} INFO - Running <TaskInstance: stock_price_prediction.run_stock_prediction manual__2025-03-03T10:48:01.103488+00:00 [running]> on host ad33c288ca81
[2025-03-03T10:51:38.594+0000] {taskinstance.py:2480} INFO - Exporting env vars: AIRFLOW_CTX_DAG_OWNER='***' AIRFLOW_CTX_DAG_ID='stock_price_prediction' AIRFLOW_CTX_TASK_ID='run_stock_prediction' AIRFLOW_CTX_EXECUTION_DATE='2025-03-03T10:48:01.103488+00:00' AIRFLOW_CTX_TRY_NUMBER='2' AIRFLOW_CTX_DAG_RUN_ID='manual__2025-03-03T10:48:01.103488+00:00'
[2025-03-03T10:51:38.629+0000] {taskinstance.py:2698} ERROR - Task failed with exception
Traceback (most recent call last):
  File "/home/airflow/.local/lib/python3.8/site-packages/airflow/models/taskinstance.py", line 433, in _execute_task
    result = execute_callable(context=context, **execute_callable_kwargs)
  File "/home/airflow/.local/lib/python3.8/site-packages/airflow/operators/python.py", line 199, in execute
    return_value = self.execute_callable()
  File "/home/airflow/.local/lib/python3.8/site-packages/airflow/operators/python.py", line 216, in execute_callable
    return self.python_callable(*self.op_args, **self.op_kwargs)
  File "/opt/airflow/dags/stock_prediction_dag.py", line 25, in run_ml_script
    subprocess.run(["python3", "/path/to/ml_pipeline.py"], check=True)
  File "/usr/local/lib/python3.8/subprocess.py", line 516, in run
    raise CalledProcessError(retcode, process.args,
subprocess.CalledProcessError: Command '['python3', '/path/to/ml_pipeline.py']' returned non-zero exit status 2.
[2025-03-03T10:51:38.645+0000] {taskinstance.py:1138} INFO - Marking task as FAILED. dag_id=stock_price_prediction, task_id=run_stock_prediction, execution_date=20250303T104801, start_date=20250303T105138, end_date=20250303T105138
[2025-03-03T10:51:38.660+0000] {standard_task_runner.py:107} ERROR - Failed to execute job 26 for task run_stock_prediction (Command '['python3', '/path/to/ml_pipeline.py']' returned non-zero exit status 2.; 93)
[2025-03-03T10:51:38.696+0000] {local_task_job_runner.py:234} INFO - Task exited with return code 1
[2025-03-03T10:51:38.711+0000] {taskinstance.py:3280} INFO - 0 downstream tasks scheduled from follow-on schedule check
