[2025-03-03T09:09:20.793+0000] {taskinstance.py:1956} INFO - Dependencies all met for dep_context=non-requeueable deps ti=<TaskInstance: stock_price_prediction.run_stock_prediction manual__2025-03-03T09:09:18.755521+00:00 [queued]>
[2025-03-03T09:09:20.804+0000] {taskinstance.py:1956} INFO - Dependencies all met for dep_context=requeueable deps ti=<TaskInstance: stock_price_prediction.run_stock_prediction manual__2025-03-03T09:09:18.755521+00:00 [queued]>
[2025-03-03T09:09:20.805+0000] {taskinstance.py:2170} INFO - Starting attempt 1 of 2
[2025-03-03T09:09:20.822+0000] {taskinstance.py:2191} INFO - Executing <Task(PythonOperator): run_stock_prediction> on 2025-03-03 09:09:18.755521+00:00
[2025-03-03T09:09:20.831+0000] {standard_task_runner.py:60} INFO - Started process 101 to run task
[2025-03-03T09:09:20.834+0000] {standard_task_runner.py:87} INFO - Running: ['***', 'tasks', 'run', 'stock_price_prediction', 'run_stock_prediction', 'manual__2025-03-03T09:09:18.755521+00:00', '--job-id', '15', '--raw', '--subdir', 'DAGS_FOLDER/stock_prediction_dag.py', '--cfg-path', '/tmp/tmpss2ah7y0']
[2025-03-03T09:09:20.837+0000] {standard_task_runner.py:88} INFO - Job 15: Subtask run_stock_prediction
[2025-03-03T09:09:20.899+0000] {task_command.py:423} INFO - Running <TaskInstance: stock_price_prediction.run_stock_prediction manual__2025-03-03T09:09:18.755521+00:00 [running]> on host 35ff2cf24a78
[2025-03-03T09:09:20.973+0000] {taskinstance.py:2480} INFO - Exporting env vars: AIRFLOW_CTX_DAG_OWNER='***' AIRFLOW_CTX_DAG_ID='stock_price_prediction' AIRFLOW_CTX_TASK_ID='run_stock_prediction' AIRFLOW_CTX_EXECUTION_DATE='2025-03-03T09:09:18.755521+00:00' AIRFLOW_CTX_TRY_NUMBER='1' AIRFLOW_CTX_DAG_RUN_ID='manual__2025-03-03T09:09:18.755521+00:00'
[2025-03-03T09:09:21.008+0000] {taskinstance.py:2698} ERROR - Task failed with exception
Traceback (most recent call last):
  File "/home/airflow/.local/lib/python3.8/site-packages/airflow/models/taskinstance.py", line 433, in _execute_task
    result = execute_callable(context=context, **execute_callable_kwargs)
  File "/home/airflow/.local/lib/python3.8/site-packages/airflow/operators/python.py", line 199, in execute
    return_value = self.execute_callable()
  File "/home/airflow/.local/lib/python3.8/site-packages/airflow/operators/python.py", line 216, in execute_callable
    return self.python_callable(*self.op_args, **self.op_kwargs)
  File "/opt/airflow/dags/stock_prediction_dag.py", line 25, in run_ml_script
    subprocess.run(["python3", "/path/to/ml_pipeline.py"], check=True)
  File "/usr/local/lib/python3.8/subprocess.py", line 516, in run
    raise CalledProcessError(retcode, process.args,
subprocess.CalledProcessError: Command '['python3', '/path/to/ml_pipeline.py']' returned non-zero exit status 2.
[2025-03-03T09:09:21.024+0000] {taskinstance.py:1138} INFO - Marking task as UP_FOR_RETRY. dag_id=stock_price_prediction, task_id=run_stock_prediction, execution_date=20250303T090918, start_date=20250303T090920, end_date=20250303T090921
[2025-03-03T09:09:21.037+0000] {standard_task_runner.py:107} ERROR - Failed to execute job 15 for task run_stock_prediction (Command '['python3', '/path/to/ml_pipeline.py']' returned non-zero exit status 2.; 101)
[2025-03-03T09:09:21.048+0000] {local_task_job_runner.py:234} INFO - Task exited with return code 1
[2025-03-03T09:09:21.068+0000] {taskinstance.py:3280} INFO - 0 downstream tasks scheduled from follow-on schedule check
